<?xml version="1.0" ?>
<robot name="bipedal_robot">
  <!-- Define the main body as a cube -->
  <link name="base_link">
    <visual>
      <geometry>
        <box size="0.3 0.3 0.3"/> <!-- Cube body -->
      </geometry>
      <material name="blue">
        <color rgba="0 0 1 1"/>
      </material>
    </visual>
    <collision>
      <geometry>
        <box size="0.3 0.3 0.3"/>
      </geometry>
    </collision>
    <inertial>
      <mass value="80.0"/>
      <origin rpy="0 0 0" xyz="0 0 0.1"/> <!-- Lower center of mass -->
      <inertia ixx="0.2" ixy="0.0" ixz="0.0" iyy="0.2" iyz="0.0" izz="0.2"/>
    </inertial>
  </link>

  <!-- Left Leg (with prismatic and rotational joints) -->
  <joint name="left_prismatic" type="prismatic">
    <parent link="base_link"/>
    <child link="left_rotational_link"/>
    <origin xyz="0 0.15 -0.15" rpy="0 0 0"/>
    <axis xyz="0 0 1"/>
    <limit lower="0" upper="0.1" effort="100.0" velocity="1.0"/>
  </joint>

  <link name="left_rotational_link">
    <inertial>
      <mass value="0.1"/>
      <inertia ixx="0.01" ixy="0" ixz="0" iyy="0.01" iyz="0" izz="0.01"/>
    </inertial>
  </link>

  <joint name="left_rotational" type="revolute">
    <parent link="left_rotational_link"/>
    <child link="left_leg"/>
    <origin xyz="0 0 -0.05" rpy="0 0 0"/>
    <axis xyz="0 1 0"/>
    <limit lower="-0.785" upper="0.785" effort="100.0" velocity="1.0"/>
  </joint>

  <link name="left_leg">
    <visual>
      <geometry>
        <cylinder radius="0.05" length="0.4"/>
      </geometry>
      <material name="red">
        <color rgba="1 0 0 1"/>
      </material>
    </visual>
    <collision>
      <geometry>
        <cylinder radius="0.05" length="0.4"/>
      </geometry>
    </collision>
    <inertial>
      <mass value="8.0"/>
      <inertia ixx="0.03" ixy="0" ixz="0" iyy="0.03" iyz="0" izz="0.03"/>
    </inertial>
  </link>

  <!-- Left Foot for Stability -->
  <link name="left_foot">
    <visual>
      <geometry>
        <box size="0.2 0.1 0.02"/>
      </geometry>
      <material name="black">
        <color rgba="0 0 0 1"/>
      </material>
    </visual>
    <collision>
      <geometry>
        <box size="0.2 0.1 0.02"/>
      </geometry>
    </collision>
    <inertial>
      <mass value="10.0"/>
      <inertia ixx="0.02" ixy="0" ixz="0" iyy="0.02" iyz="0" izz="0.02"/>
    </inertial>
  </link>

  <joint name="left_foot_joint" type="fixed">
    <parent link="left_leg"/>
    <child link="left_foot"/>
    <origin xyz="0 0 -0.2" rpy="0 0 0"/>
  </joint>

  <!-- Right Leg (with prismatic and rotational joints) -->
  <joint name="right_prismatic" type="prismatic">
    <parent link="base_link"/>
    <child link="right_rotational_link"/>
    <origin xyz="0 -0.15 -0.15" rpy="0 0 0"/>
    <axis xyz="0 0 1"/>
    <limit lower="0" upper="0.1" effort="100.0" velocity="1.0"/>
  </joint>

  <link name="right_rotational_link">
    <inertial>
      <mass value="0.1"/>
      <inertia ixx="0.01" ixy="0" ixz="0" iyy="0.01" iyz="0" izz="0.01"/>
    </inertial>
  </link>

  <joint name="right_rotational" type="revolute">
    <parent link="right_rotational_link"/>
    <child link="right_leg"/>
    <origin xyz="0 0 -0.05" rpy="0 0 0"/>
    <axis xyz="0 1 0"/>
    <limit lower="-0.785" upper="0.785" effort="100.0" velocity="1.0"/>
  </joint>

  <link name="right_leg">
    <visual>
      <geometry>
        <cylinder radius="0.05" length="0.4"/>
      </geometry>
      <material name="red">
        <color rgba="1 0 0 1"/>
      </material>
    </visual>
    <collision>
      <geometry>
        <cylinder radius="0.05" length="0.4"/>
      </geometry>
    </collision>
    <inertial>
      <mass value="8.0"/>
      <inertia ixx="0.03" ixy="0" ixz="0" iyy="0.03" iyz="0" izz="0.03"/>
    </inertial>
  </link>

  <!-- Right Foot for Stability -->
  <link name="right_foot">
    <visual>
      <geometry>
        <box size="0.2 0.1 0.02"/>
      </geometry>
      <material name="black">
        <color rgba="0 0 0 1"/>
      </material>
    </visual>
    <collision>
      <geometry>
        <box size="0.2 0.1 0.02"/>
      </geometry>
    </collision>
    <inertial>
      <mass value="10.0"/>
      <inertia ixx="0.02" ixy="0" ixz="0" iyy="0.02" iyz="0" izz="0.02"/>
    </inertial>
  </link>

  <joint name="right_foot_joint" type="fixed">
    <parent link="right_leg"/>
    <child link="right_foot"/>
    <origin xyz="0 0 -0.2" rpy="0 0 0"/>
  </joint>
</robot>
