<?xml version="1.0" ?>
<robot name="quadruped_robot">
  <!-- Define the main body -->
  <link name="base_link">
    <visual>
      <geometry>
        <box size="0.6 0.6 0.1"/> <!-- Square body: length and width 0.6, height remains 0.1 -->
      </geometry>
      <material name="blue">
        <color rgba="0 0 1 1"/>
      </material>
    </visual>
    <collision>
      <geometry>
        <box size="0.6 0.6 0.1"/>
      </geometry>
    </collision>
    <inertial>
      <mass value="40.0"/>
      <origin rpy="0 0 0" xyz="0 0 0"/>
      <inertia ixx="0.1" ixy="0.0" ixz="0.0" iyy="0.1" iyz="0.0" izz="0.1"/>
    </inertial>
  </link>

  <!-- Front Left Leg (with prismatic and rotational joints) -->
  <joint name="front_left_prismatic" type="prismatic">
    <parent link="base_link"/>
    <child link="front_left_rotational_link"/>
    <origin xyz="0.3 0.3 -0.2" rpy="0 0 0"/> <!-- Prismatic joint starts 0.2 units below to attach closer to the top of the leg -->
    <axis xyz="0 0 1"/> <!-- Vertical movement -->
    <limit lower="0" upper="0.1" effort="100.0" velocity="1.0"/>
  </joint>

  <!-- No visual geometry for the rotational link -->
  <link name="front_left_rotational_link">
    <inertial>
      <mass value="0.1"/>
      <inertia ixx="0.01" ixy="0" ixz="0" iyy="0.01" iyz="0" izz="0.01"/>
    </inertial>
  </link>

  <joint name="front_left_rotational" type="revolute">
    <parent link="front_left_rotational_link"/>
    <child link="front_left_leg"/>
    <origin xyz="0 0 -0.05" rpy="0 0 0"/> <!-- Offset for the rotational joint -->
    <axis xyz="0 1 0"/> <!-- Rotates around the y-axis -->
    <limit lower="-0.785" upper="0.785" effort="100.0" velocity="1.0"/>
  </joint>

  <link name="front_left_leg">
    <visual>
      <geometry>
        <cylinder radius="0.05" length="0.6"/> <!-- Cylinder leg: shortened length from 1 to 0.6 -->
      </geometry>
      <material name="green">
        <color rgba="0 1 0 1"/>
      </material>
    </visual>
    <collision>
      <geometry>
        <cylinder radius="0.05" length="0.6"/>
      </geometry>
    </collision>
    <inertial>
      <mass value="5"/>
      <inertia ixx="0.02" ixy="0" ixz="0" iyy="0.02" iyz="0" izz="0.02"/>
    </inertial>
  </link>

  <!-- Front Right Leg (with prismatic and rotational joints) -->
  <joint name="front_right_prismatic" type="prismatic">
    <parent link="base_link"/>
    <child link="front_right_rotational_link"/>
    <origin xyz="0.3 -0.3 -0.2" rpy="0 0 0"/> <!-- Prismatic joint starts 0.2 units below to attach closer to the top of the leg -->
    <axis xyz="0 0 1"/> <!-- Vertical movement -->
    <limit lower="0" upper="0.1" effort="100.0" velocity="1.0"/>
  </joint>

  <!-- No visual geometry for the rotational link -->
  <link name="front_right_rotational_link">
    <inertial>
      <mass value="0.1"/>
      <inertia ixx="0.01" ixy="0" ixz="0" iyy="0.01" iyz="0" izz="0.01"/>
    </inertial>
  </link>

  <joint name="front_right_rotational" type="revolute">
    <parent link="front_right_rotational_link"/>
    <child link="front_right_leg"/>
    <origin xyz="0 0 -0.05" rpy="0 0 0"/> <!-- Offset for the rotational joint -->
    <axis xyz="0 1 0"/> <!-- Rotates around the y-axis -->
    <limit lower="-0.785" upper="0.785" effort="100.0" velocity="1.0"/>
  </joint>

  <link name="front_right_leg">
    <visual>
      <geometry>
        <cylinder radius="0.05" length="0.6"/> <!-- Cylinder leg: shortened length from 1 to 0.6 -->
      </geometry>
      <material name="red">
        <color rgba="1 0 0 1"/>
      </material>
    </visual>
    <collision>
      <geometry>
        <cylinder radius="0.05" length="0.6"/>
      </geometry>
    </collision>
    <inertial>
      <mass value="5"/>
      <inertia ixx="0.02" ixy="0" ixz="0" iyy="0.02" iyz="0" izz="0.02"/>
    </inertial>
  </link>

  <!-- Back Left Leg (with prismatic and rotational joints) -->
  <joint name="back_left_prismatic" type="prismatic">
    <parent link="base_link"/>
    <child link="back_left_rotational_link"/>
    <origin xyz="-0.3 0.3 -0.2" rpy="0 0 0"/> <!-- Prismatic joint starts 0.2 units below to attach closer to the top of the leg -->
    <axis xyz="0 0 1"/> <!-- Vertical movement -->
    <limit lower="0" upper="0.1" effort="100.0" velocity="1.0"/>
  </joint>

  <!-- No visual geometry for the rotational link -->
  <link name="back_left_rotational_link">
    <inertial>
      <mass value="0.1"/>
      <inertia ixx="0.01" ixy="0" ixz="0" iyy="0.01" iyz="0" izz="0.01"/>
    </inertial>
  </link>

  <joint name="back_left_rotational" type="revolute">
    <parent link="back_left_rotational_link"/>
    <child link="back_left_leg"/>
    <origin xyz="0 0 -0.05" rpy="0 0 0"/> <!-- Offset for the rotational joint -->
    <axis xyz="0 1 0"/> <!-- Rotates around the y-axis -->
    <limit lower="-0.785" upper="0.785" effort="100.0" velocity="1.0"/>
  </joint>

  <link name="back_left_leg">
    <visual>
      <geometry>
        <cylinder radius="0.05" length="0.6"/> <!-- Cylinder leg: shortened length from 1 to 0.6 -->
      </geometry>
      <material name="red">
        <color rgba="1 0 0 1"/>
      </material>
    </visual>
    <collision>
      <geometry>
        <cylinder radius="0.05" length="0.6"/>
      </geometry>
    </collision>
    <inertial>
      <mass value="5"/>
      <inertia ixx="0.02" ixy="0" ixz="0" iyy="0.02" iyz="0" izz="0.02"/>
    </inertial>
  </link>

  <!-- Back Right Leg (with prismatic and rotational joints) -->
  <joint name="back_right_prismatic" type="prismatic">
    <parent link="base_link"/>
    <child link="back_right_rotational_link"/>
    <origin xyz="-0.3 -0.3 -0.2" rpy="0 0 0"/> <!-- Prismatic joint starts 0.2 units below to attach closer to the top of the leg -->
    <axis xyz="0 0 1"/> <!-- Vertical movement -->
    <limit lower="0" upper="0.1" effort="100.0" velocity="1.0"/>
  </joint>

  <!-- No visual geometry for the rotational link -->
  <link name="back_right_rotational_link">
    <inertial>
      <mass value="0.1"/>
      <inertia ixx="0.01" ixy="0" ixz="0" iyy="0.01" iyz="0" izz="0.01"/>
    </inertial>
  </link>

  <joint name="back_right_rotational" type="revolute">
    <parent link="back_right_rotational_link"/>
    <child link="back_right_leg"/>
    <origin xyz="0 0 -0.05" rpy="0 0 0"/> <!-- Offset for the rotational joint -->
    <axis xyz="0 1 0"/> <!-- Rotates around the y-axis -->
    <limit lower="-0.785" upper="0.785" effort="100.0" velocity="1.0"/>
  </joint>

  <link name="back_right_leg">
    <visual>
      <geometry>
        <cylinder radius="0.05" length="0.6"/> <!-- Cylinder leg: shortened length from 1 to 0.6 -->
      </geometry>
      <material name="red">
        <color rgba="1 0 0 1"/>
      </material>
    </visual>
    <collision>
      <geometry>
        <cylinder radius="0.05" length="0.6"/>
      </geometry>
    </collision>
    <inertial>
      <mass value="5"/>
      <inertia ixx="0.02" ixy="0" ixz="0" iyy="0.02" iyz="0" izz="0.02"/>
    </inertial>
  </link>

</robot>
