<?xml version="1.0" ?>
<robot name="quadruped_robot">
  <!-- Define the main body -->
  <link name="base_link">
    <visual>
      <geometry>
        <box size="0.6 0.6 0.1"/> <!-- Square body: length and width 0.6, height remains 0.1 -->
      </geometry>
      <material name="blue">
        <color rgba="0 0 1 1"/>
      </material>
    </visual>
    <collision>
      <geometry>
        <box size="0.6 0.6 0.1"/>
      </geometry>
    </collision>
    <inertial>
      <mass value="2.0"/>
      <origin rpy="0 0 0" xyz="0 0 0"/>
      <inertia ixx="0.1" ixy="0.0" ixz="0.0" iyy="0.1" iyz="0.0" izz="0.1"/>
    </inertial>
  </link>

  <!-- Front Left Leg -->
  <!-- Continuous Joint for rotational movement -->
  <joint name="front_left_rotational" type="continuous">
    <parent link="base_link"/>
    <child link="front_left_leg"/>
    <origin xyz="0.3 0.3 -0.05" rpy="0 0 0"/> <!-- Move leg to corner of square base -->
    <axis xyz="0 1 0"/> <!-- Rotational movement along y-axis -->
    <limit effort="100.0" velocity="1.0"/>
  </joint>

  <!-- Front Left Leg Link (cylinder) -->
  <link name="front_left_leg">
    <visual>
      <geometry>
        <cylinder radius="0.05" length="0.3"/> <!-- Cylinder leg dimensions: radius 0.05, length 0.3 -->
      </geometry>
      <material name="red">
        <color rgba="1 0 0 1"/>
      </material>
    </visual>
    <collision>
      <geometry>
        <cylinder radius="0.05" length="0.3"/>
      </geometry>
    </collision>
    <inertial>
      <mass value="0.4"/>
      <origin rpy="0 0 0" xyz="0 0 0"/>
      <inertia ixx="0.02" ixy="0.0" ixz="0.0" iyy="0.02" iyz="0.0" izz="0.02"/>
    </inertial>
  </link>

  <!-- Front Right Leg -->
  <!-- Continuous Joint for rotational movement -->
  <joint name="front_right_rotational" type="continuous">
    <parent link="base_link"/>
    <child link="front_right_leg"/>
    <origin xyz="0.3 -0.3 -0.05" rpy="0 0 0"/> <!-- Move leg to corner of square base -->
    <axis xyz="0 1 0"/>
    <limit effort="100.0" velocity="1.0"/>
  </joint>

  <!-- Front Right Leg Link (cylinder) -->
  <link name="front_right_leg">
    <visual>
      <geometry>
        <cylinder radius="0.05" length="0.3"/>
      </geometry>
      <material name="red">
        <color rgba="1 0 0 1"/>
      </material>
    </visual>
    <collision>
      <geometry>
        <cylinder radius="0.05" length="0.3"/>
      </geometry>
    </collision>
    <inertial>
      <mass value="0.4"/>
      <origin rpy="0 0 0" xyz="0 0 0"/>
      <inertia ixx="0.02" ixy="0.0" ixz="0.0" iyy="0.02" iyz="0.0" izz="0.02"/>
    </inertial>
  </link>

  <!-- Back Left Leg -->
  <!-- Continuous Joint for rotational movement -->
  <joint name="back_left_rotational" type="continuous">
    <parent link="base_link"/>
    <child link="back_left_leg"/>
    <origin xyz="-0.3 0.3 -0.05" rpy="0 0 0"/> <!-- Move leg to corner of square base -->
    <axis xyz="0 1 0"/>
    <limit effort="100.0" velocity="1.0"/>
  </joint>

  <!-- Back Left Leg Link (cylinder) -->
  <link name="back_left_leg">
    <visual>
      <geometry>
        <cylinder radius="0.05" length="0.3"/>
      </geometry>
      <material name="red">
        <color rgba="1 0 0 1"/>
      </material>
    </visual>
    <collision>
      <geometry>
        <cylinder radius="0.05" length="0.3"/>
      </geometry>
    </collision>
    <inertial>
      <mass value="0.4"/>
      <origin rpy="0 0 0" xyz="0 0 0"/>
      <inertia ixx="0.02" ixy="0.0" ixz="0.0" iyy="0.02" iyz="0.0" izz="0.02"/>
    </inertial>
  </link>

  <!-- Back Right Leg -->
  <!-- Continuous Joint for rotational movement -->
  <joint name="back_right_rotational" type="continuous">
    <parent link="base_link"/>
    <child link="back_right_leg"/>
    <origin xyz="-0.3 -0.3 -0.05" rpy="0 0 0"/> <!-- Move leg to corner of square base -->
    <axis xyz="0 1 0"/>
    <limit effort="100.0" velocity="1.0"/>
  </joint>

  <!-- Back Right Leg Link (cylinder) -->
  <link name="back_right_leg">
    <visual>
      <geometry>
        <cylinder radius="0.05" length="0.3"/>
      </geometry>
      <material name="red">
        <color rgba="1 0 0 1"/>
      </material>
    </visual>
    <collision>
      <geometry>
        <cylinder radius="0.05" length="0.3"/>
      </geometry>
    </collision>
    <inertial>
      <mass value="0.4"/>
      <origin rpy="0 0 0" xyz="0 0 0"/>
      <inertia ixx="0.02" ixy="0.0" ixz="0.0" iyy="0.02" iyz="0.0" izz="0.02"/>
    </inertial>
  </link>
</robot>
